2024-05-22 08:22:21,438 ERROR scheduler Exception in Enqueue Events for Site actions.localhost
Traceback (most recent call last):
  File "/home/fong/Downloads/responsive-image-slider-html-css-javascript/bench-traning/programing_bench/apps/frappe/frappe/utils/scheduler.py", line 84, in enqueue_events_for_site
    if is_scheduler_inactive():
  File "/home/fong/Downloads/responsive-image-slider-html-css-javascript/bench-traning/programing_bench/apps/frappe/frappe/utils/scheduler.py", line 126, in is_scheduler_inactive
    if is_scheduler_disabled(verbose=verbose):
  File "/home/fong/Downloads/responsive-image-slider-html-css-javascript/bench-traning/programing_bench/apps/frappe/frappe/utils/scheduler.py", line 139, in is_scheduler_disabled
    frappe.db.get_single_value("System Settings", "enable_scheduler")
  File "/home/fong/Downloads/responsive-image-slider-html-css-javascript/bench-traning/programing_bench/apps/frappe/frappe/database/database.py", line 846, in get_single_value
    ).run()
  File "/home/fong/Downloads/responsive-image-slider-html-css-javascript/bench-traning/programing_bench/apps/frappe/frappe/query_builder/utils.py", line 84, in execute_query
    result = frappe.db.sql(query, params, *args, **kwargs)  # nosemgrep
  File "/home/fong/Downloads/responsive-image-slider-html-css-javascript/bench-traning/programing_bench/apps/frappe/frappe/database/database.py", line 213, in sql
    self.connect()
  File "/home/fong/Downloads/responsive-image-slider-html-css-javascript/bench-traning/programing_bench/apps/frappe/frappe/database/database.py", line 118, in connect
    self._conn: "MariadbConnection" | "PostgresConnection" = self.get_connection()
  File "/home/fong/Downloads/responsive-image-slider-html-css-javascript/bench-traning/programing_bench/apps/frappe/frappe/database/mariadb/database.py", line 107, in get_connection
    conn = self._get_connection()
  File "/home/fong/Downloads/responsive-image-slider-html-css-javascript/bench-traning/programing_bench/apps/frappe/frappe/database/mariadb/database.py", line 113, in _get_connection
    return self.create_connection()
  File "/home/fong/Downloads/responsive-image-slider-html-css-javascript/bench-traning/programing_bench/apps/frappe/frappe/database/mariadb/database.py", line 116, in create_connection
    return pymysql.connect(**self.get_connection_settings())
  File "/home/fong/Downloads/responsive-image-slider-html-css-javascript/bench-traning/programing_bench/env/lib/python3.10/site-packages/pymysql/connections.py", line 358, in __init__
    self.connect()
  File "/home/fong/Downloads/responsive-image-slider-html-css-javascript/bench-traning/programing_bench/env/lib/python3.10/site-packages/pymysql/connections.py", line 664, in connect
    self._request_authentication()
  File "/home/fong/Downloads/responsive-image-slider-html-css-javascript/bench-traning/programing_bench/env/lib/python3.10/site-packages/pymysql/connections.py", line 954, in _request_authentication
    auth_packet = self._read_packet()
  File "/home/fong/Downloads/responsive-image-slider-html-css-javascript/bench-traning/programing_bench/env/lib/python3.10/site-packages/pymysql/connections.py", line 772, in _read_packet
    packet.raise_for_error()
  File "/home/fong/Downloads/responsive-image-slider-html-css-javascript/bench-traning/programing_bench/env/lib/python3.10/site-packages/pymysql/protocol.py", line 221, in raise_for_error
    err.raise_mysql_exception(self._data)
  File "/home/fong/Downloads/responsive-image-slider-html-css-javascript/bench-traning/programing_bench/env/lib/python3.10/site-packages/pymysql/err.py", line 143, in raise_mysql_exception
    raise errorclass(errno, errval)
pymysql.err.OperationalError: (1045, "Access denied for user '_a0a23713f55e6e4f'@'localhost' (using password: YES)")
